<mujoco model="balance_bot">
  <option timestep="0.005" gravity="0 0 -9.81"/>

  <visual>
    <rgba haze="0.15 0.25 0.35 1"/>
    <quality shadowsize="2048"/>
  </visual>

  <worldbody>
    <light pos="0 0 3" dir="0 0 -1" directional="true"/>
    
    <geom name="floor" type="plane" size="0 0 0.05" rgba=".8 .9 .8 1" euler="0 35 0"/>

    <body name="robot" pos="0 0 0.05" euler="0 35 0">
      <joint name="slide_x" type="slide" axis="1 0 0" damping="0.1"/>
      <joint name="pitch" type="hinge" axis="0 1 0" pos="0 0 0"/>
      
      <camera name="chase" mode="fixed" pos="-0.8 0 0.4" xyaxes="0 -1 0 0 0 1"/>

      <geom type="box" size="0.05 0.05 0.2" pos="0 0 0.2" rgba="0.9 0.5 0.1 1" mass="1.5"/>

      <body name="wheel_r" pos="0 -0.15 0">
        <joint name="motor_r" axis="0 1 0"/>
        <geom type="cylinder" size="0.05 0.02" rgba="0.1 0.1 0.1 1" mass="0.5" fromto="0 0 0 0 0.02 0"/>
      </body>

      <body name="wheel_l" pos="0 0.15 0">
        <joint name="motor_l" axis="0 1 0"/>
        <geom type="cylinder" size="0.05 0.02" rgba="0.1 0.1 0.1 1" mass="0.5" fromto="0 0 0 0 -0.02 0"/>
      </body>
    </body>

    <camera name="tracking_cam" mode="track" target="robot" pos="-1.5 0 1" xyaxes="0 -1 0 0 0 1"/>

  </worldbody>

  <actuator>
    <motor name="left" joint="motor_l" gear="0.25"/>
    <motor name="right" joint="motor_r" gear="0.25"/>
  </actuator>
</mujoco>